Workbook

Sheet Collected Data
A1: Participant | B1: Base | C1: VS-VS | D1: VS-VV | E1: VS-AV | F1: VS-AS | H1: Collected Data Summary Table
A2: 1 | B2: 10 | C2: 69 | D2: 56 | E2: 57 | F2: 56
A3: 2 | B3: 20 | C3: 79 | D3: 76 | E3: 63 | F3: 54 | I3: Base | J3: VS-VS | K3: VS-VV | L3: VS-AV | M3: VS-AS
A4: 3 | B4: 10 | C4: 87 | D4: 98 | E4: 73 | F4: 76 | H4: Mean | I4: =AVERAGE(B2:B101) -> 17.4 | J4: =AVERAGE(C2:C101) -> 95.2 | K4: =AVERAGE(D2:D101) -> 99.5 | L4: =AVERAGE(E2:E101) -> 88.9 | M4: =AVERAGE(F2:F101) -> 90.9
A5: 4 | B5: 10 | C5: 103 | D5: 98 | E5: 80 | F5: 114 | H5: Std. Dev. | I5: =STDEV(B2:B101) -> 8.4353752 | J5: =STDEV(C2:C101) -> 32.563784 | K5: =STDEV(D2:D101) -> 53.310933 | L5: =STDEV(E2:E101) -> 47.526484 | M5: =STDEV(F2:F101) -> 41.964138
A6: 5 | B6: 30 | C6: 170 | D6: 241 | E6: 174 | F6: 172 | H6: 25th Pct | I6: =PERCENTILE(B2:B101,0.25) -> 10 | J6: =PERCENTILE(C2:C101,0.25) -> 72.25 | K6: =PERCENTILE(D2:D101,0.25) -> 72.25 | L6: =PERCENTILE(E2:E101,0.25) -> 58.5 | M6: =PERCENTILE(F2:F101,0.25) -> 56.75
A7: 6 | B7: 20 | C7: 63 | D7: 61 | E7: 45 | F7: 53 | H7: Median | I7: =MEDIAN(B2:B101) -> 16 | J7: =MEDIAN(C2:C101) -> 83 | K7: =MEDIAN(D2:D101) -> 87.5 | L7: =MEDIAN(E2:E101) -> 72.5 | M7: =MEDIAN(F2:F101) -> 71.5
A8: 7 | B8: 10 | C8: 122 | D8: 119 | E8: 177 | F8: 131 | H8: 75th Pct | I8: =PERCENTILE(B2:B101,0.75) -> 20 | J8: =PERCENTILE(C2:C101,0.75) -> 108.25 | K8: =PERCENTILE(D2:D101,0.75) -> 98 | L8: =PERCENTILE(E2:E101,0.75) -> 89 | M8: =PERCENTILE(F2:F101,0.75) -> 123.75
A9: 8 | B9: 20 | C9: 70 | D9: 79 | E9: 56 | F9: 59 | H9: IQR | I9: =I8-I6 -> 10 | J9: =J8-J6 -> 36 | K9: =K8-K6 -> 25.75 | L9: =L8-L6 -> 30.5 | M9: =M8-M6 -> 67
A10: 9 | B10: 12 | C10: 79 | D10: 71 | E10: 72 | F10: 67 | H10: Minimum | I10: =MIN(B2:B101) -> 10 | J10: =MIN(C2:C101) -> 63 | K10: =MIN(D2:D101) -> 56 | L10: =MIN(E2:E101) -> 45 | M10: =MIN(F2:F101) -> 53
A11: 10 | B11: 32 | C11: 110 | D11: 96 | E11: 92 | F11: 127 | H11: Maximum | I11: =MAX(B2:B101) -> 32 | J11: =MAX(C2:C101) -> 170 | K11: =MAX(D2:D101) -> 241 | L11: =MAX(E2:E101) -> 177 | M11: =MAX(F2:F101) -> 172
H12: Variance | I12: =VAR(B2:B101) -> 71.155556 | J12: =VAR(C2:C101) -> 1060.4 | K12: =VAR(D2:D101) -> 2842.0556 | L12: =VAR(E2:E101) -> 2258.7667 | M12: =VAR(F2:F101) -> 1760.9889

Sheet Data Collection
B1: Tracking Score (Error in Px) | F1: Threat Response Score (Hits/Total) | J1: Frustration TLX | N1: Performance TLX | R1: Mental Demand TLX | X1: Tracking Score (Error in Px) | AB1: Threat Response Score (Hits/Total) | AF1: Frustration TLX | AJ1: Performance TLX | AN1: Mental Demand TLX
A2: Participant | B2: VS-VS | C2: VS-VV | D2: VS-AV | E2: VS-AS | F2: VS-VS | G2: VS-VV | H2: VS-AV | I2: VS-AS | J2: VS-VS | K2: VS-VV | L2: VS-AV | M2: VS-AS | N2: VS-VS | O2: VS-VV | P2: VS-AV | Q2: VS-AS | R2: VS-VS | S2: VS-VV | T2: VS-AV | U2: VS-AS | X2: VS-VS | Y2: VS-VV | Z2: VS-AV | AA2: VS-AS | AB2: VS-VS | AC2: VS-VV | AD2: VS-AV | AE2: VS-AS | AF2: VS-VS | AG2: VS-VV | AH2: VS-AV | AI2: VS-AS | AJ2: VS-VS | AK2: VS-VV | AL2: VS-AV | AM2: VS-AS | AN2: VS-VS | AO2: VS-VV | AP2: VS-AV | AQ2: VS-AS
A3: 1 | B3: 69 | C3: 56 | D3: 57 | E3: 56 | F3: 46179 | G3: 46118 | H3: 46179 | I3: 46117 | J3: 40 | K3: 50 | L3: 5 | M3: 35 | N3: 35 | O3: 45 | P3: 5 | Q3: 30 | R3: 30 | S3: 40 | T3: 15 | U3: 20 | W3: Mean | X3: =(AVERAGE(B3:B52)) -> 84.325 | Y3: =(AVERAGE(C3:C39)) -> 82.648649 | Z3: =(AVERAGE(D3:D39)) -> 80.243243 | AA3: =(AVERAGE(E3:E39)) -> 79.243243 | AB3: =ANOVA!M4 -> 0.92612613 | AC3: =ANOVA!N4 -> 0.86396396 | AD3: =ANOVA!O4 -> 0.89009009 | AE3: =ANOVA!P4 -> 0.92314815 | AF3: =(AVERAGE(J3:J52)) -> 38.125 | AG3: =(AVERAGE(K3:K52)) -> 39.25 | AH3: =(AVERAGE(L3:L52)) -> 36.875 | AI3: =(AVERAGE(M3:M52)) -> 33 | AJ3: =(AVERAGE(N3:N52)) -> 38.375 | AK3: =(AVERAGE(O3:O52)) -> 40.75 | AL3: =(AVERAGE(P3:P52)) -> 41.5 | AM3: =(AVERAGE(Q3:Q52)) -> 39.75 | ... AQ3: =(AVERAGE(U3:U52)) -> 41
A4: 2 | B4: 79 | C4: 76 | D4: 63 | E4: 54 | F4: 46179 | G4: 46179 | H4: 46148 | I4: 46179 | J4: 0 | K4: 35 | L4: 25 | M4: 0 | N4: 20 | O4: 30 | P4: 35 | Q4: 5 | R4: 90 | S4: 90 | T4: 30 | U4: 35 | W4: Standard Deviation | X4: =STDEV(B3:B52) -> 26.444317 | Y4: =STDEV(C3:C39) -> 33.316009 | Z4: =STDEV(D3:D39) -> 35.241552 | AA4: =STDEV(E3:E39) -> 28.39934 | AB4: =ANOVA!M5 -> 0.12301138 | AC4: =ANOVA!N5 -> 0.12750657 | AD4: =ANOVA!O5 -> 0.13830206 | AE4: =ANOVA!P5 -> 0.096220463 | AF4: =STDEV(J3:J52) -> 24.32914 | AG4: =STDEV(K3:K52) -> 22.203892 | AH4: =STDEV(L3:L52) -> 26.425694 | AI4: =STDEV(M3:M52) -> 25.665501 | AJ4: =STDEV(N3:N52) -> 20.643106 | AK4: =STDEV(O3:O52) -> 16.891433 | AL4: =STDEV(P3:P52) -> 23.890777 | AM4: =STDEV(Q3:Q52) -> 23.586991 | ... AQ4: =STDEV(U3:U52) -> 19.55269
A5: 3 | B5: 87 | C5: 98 | D5: 73 | E5: 76 | F5: 46147 | G5: 46118 | H5: 46118 | I5: 46147 | J5: 25 | K5: 25 | L5: 10 | M5: 5 | N5: 35 | O5: 65 | P5: 45 | Q5: 30 | R5: 35 | S5: 30 | T5: 25 | U5: 15
A6: 4 | B6: 103 | C6: 98 | D6: 80 | E6: 114 | F6: 46147 | G6: 46117 | H6: 46179 | I6: 46179 | J6: 15 | K6: 30 | L6: 0 | M6: 5 | N6: 55 | O6: 40 | P6: 80 | Q6: 45 | R6: 25 | S6: 30 | T6: 0 | U6: 10
A7: 5 | B7: 170 | C7: 241 | D7: 174 | E7: 172 | F7: 46179 | G7: 46086 | H7: 46147 | I7: 46148 | J7: 40 | K7: 75 | L7: 80 | M7: 40 | N7: 45 | O7: 40 | P7: 35 | Q7: 60 | R7: 45 | S7: 65 | T7: 65 | U7: 35
A8: 6 | B8: 63 | C8: 61 | D8: 45 | E8: 53 | F8: 46147 | G8: 46148 | H8: 46179 | I8: 46147 | J8: 15 | K8: 15 | L8: 30 | M8: 65 | N8: 30 | O8: 75 | P8: 10 | Q8: 35 | R8: 75 | S8: 30 | T8: 65 | U8: 60
A9: 7 | B9: 122 | C9: 119 | D9: 177 | E9: 131 | F9: 46147 | G9: 46179 | H9: 46148 | I9: 46147 | J9: 55 | K9: 45 | L9: 65 | M9: 60 | N9: 80 | O9: 35 | P9: 35 | Q9: 45 | R9: 45 | S9: 40 | T9: 45 | U9: 55
A10: 8 | B10: 70 | C10: 79 | D10: 56 | E10: 59 | F10: 46179 | G10: 46147 | H10: 46179 | I10: 46147 | J10: 30 | K10: 70 | L10: 70 | M10: 20 | N10: 20 | O10: 20 | P10: 15 | Q10: 15 | R10: 60 | S10: 35 | T10: 80 | U10: 65
A11: 9 | B11: 79 | C11: 71 | D11: 72 | E11: 67 | F11: 46147 | G11: 46148 | H11: 46148 | I11: 46148 | J11: 40 | K11: 65 | L11: 25 | M11: 5 | N11: 0 | O11: 35 | P11: 20 | Q11: 15 | R11: 25 | S11: 75 | T11: 25 | U11: 15
A12: 10 | B12: 110 | C12: 96 | D12: 92 | E12: 127 | F12: 46117 | G12: 46179 | H12: 46147 | I12: 46179 | J12: 30 | K12: 20 | L12: 15 | M12: 25 | N12: 60 | O12: 65 | P12: 70 | Q12: 60 | R12: 55 | S12: 35 | T12: 20 | U12: 30
A13: 11 | B13: 90 | C13: 106 | D13: 90 | E13: 80 | F13: 46148 | G13: 46148 | H13: 46179 | I13: 46179 | J13: 55 | K13: 65 | L13: 80 | M13: 70 | N13: 45 | O13: 35 | P13: 70 | Q13: 65 | R13: 70 | S13: 80 | T13: 85 | U13: 60
A14: 12 | B14: 62 | C14: 63 | D14: 92 | E14: 60 | F14: 46147 | G14: 46118 | H14: 46179 | I14: 46147 | J14: 45 | K14: 50 | L14: 40 | M14: 45 | N14: 25 | O14: 60 | P14: 40 | Q14: 30 | R14: 85 | S14: 90 | T14: 35 | U14: 30
A15: 13 | B15: 94 | C15: 84 | D15: 82 | E15: 78 | F15: 46179 | G15: 46117 | H15: 46179 | I15: 46148 | J15: 25 | K15: 35 | L15: 50 | M15: 45 | N15: 45 | O15: 40 | P15: 40 | Q15: 45 | R15: 50 | S15: 50 | T15: 35 | U15: 45
A16: 14 | B16: 48 | C16: 50 | D16: 47 | E16: 53 | F16: 46087 | G16: 46117 | H16: 46179 | I16: 46118 | J16: 90 | K16: 5 | L16: 5 | M16: 75 | N16: 10 | O16: 90 | P16: 70 | Q16: 65 | R16: 85 | S16: 10 | T16: 15 | U16: 20
... A42: 40 | B42: 59 | C42: 56 | D42: 55 | E42: 53 | F42: 46147 | G42: 46117 | H42: 46147 | I42: 46179 | J42: 20 | K42: 40 | L42: 30 | M42: 10 | N42: 20 | O42: 40 | P42: 30 | Q42: 20 | R42: 30 | S42: 40 | T42: 50 | U42: 20
A43: 41
A44: 42
A45: 43
A46: 44
A47: 45
A48: 46
A49: 47
A50: 48
A51: 49
A52: 50
B54: Tracking Score (Error in Px) | F54: Threat Response Score (Hits/Total) | J54: Frustration TLX | N54: Performance TLX | R54: Mental Demand TLX
A55: Participant | B55: VS-VS | C55: VS-VV | D55: VS-AV | E55: VS-AS | F55: VS-VS | G55: VS-VV | H55: VS-AV | I55: VS-AS | J55: VS-VS | K55: VS-VV | L55: VS-AV | M55: VS-AS | N55: VS-VS | O55: VS-VV | P55: VS-AV | Q55: VS-AS | R55: VS-VS | S55: VS-VV | T55: VS-AV | U55: VS-AS
A56: 1 | B56: 69 | C56: 56 | D56: 57 | E56: 56 | F56: =MONTH(F3)/DAY(F3) -> 1 | G56: =MONTH(G3)/DAY(G3) -> 0.66666667 | H56: =MONTH(H3)/DAY(H3) -> 1 | I56: =MONTH(I3)/DAY(I3) -> 0.8 | J56: 40 | K56: 50 | L56: 5 | M56: 35 | N56: 35 | O56: 45 | P56: 5 | Q56: 30 | R56: 30 | S56: 40 | T56: 15 | U56: 20
A57: 2 | B57: 79 | C57: 76 | D57: 63 | E57: 54 | F57: =MONTH(F4)/DAY(F4) -> 1 | G57: =MONTH(G4)/DAY(G4) -> 1 | H57: =MONTH(H4)/DAY(H4) -> 0.83333333 | I57: =MONTH(I4)/DAY(I4) -> 1 | J57: 0 | K57: 35 | L57: 25 | M57: 0 | N57: 20 | O57: 30 | P57: 35 | Q57: 5 | R57: 90 | S57: 90 | T57: 30 | U57: 35
A58: 3 | B58: 87 | C58: 98 | D58: 73 | E58: 76 | F58: =MONTH(F5)/DAY(F5) -> 1 | G58: =MONTH(G5)/DAY(G5) -> 0.66666667 | H58: =MONTH(H5)/DAY(H5) -> 0.66666667 | I58: =MONTH(I5)/DAY(I5) -> 1 | J58: 25 | K58: 25 | L58: 10 | M58: 5 | N58: 35 | O58: 65 | P58: 45 | Q58: 30 | R58: 35 | S58: 30 | T58: 25 | U58: 15
A59: 4 | B59: 103 | C59: 98 | D59: 80 | E59: 114 | F59: =MONTH(F6)/DAY(F6) -> 1 | G59: =MONTH(G6)/DAY(G6) -> 0.8 | H59: =MONTH(H6)/DAY(H6) -> 1 | I59: =MONTH(I6)/DAY(I6) -> 1 | J59: 15 | K59: 30 | L59: 0 | M59: 5 | N59: 55 | O59: 40 | P59: 80 | Q59: 45 | R59: 25 | S59: 30 | T59: 0 | U59: 10
A60: 5 | B60: 75 | C60: 60 | D60: 51 | E60: 57 | F60: 0.83333333 | G60: 0.8 | H60: 1 | I60: 0.66666667 | J60: 15 | K60: 5 | L60: 0 | M60: 0 | N60: 50 | O60: 20 | P60: 5 | Q60: 25 | R60: 60 | S60: 35 | T60: 10 | U60: 25
A61: 6 | B61: 63 | C61: 61 | D61: 45 | E61: 53 | F61: =MONTH(F8)/DAY(F8) -> 1 | G61: =MONTH(G8)/DAY(G8) -> 0.83333333 | H61: =MONTH(H8)/DAY(H8) -> 1 | I61: =MONTH(I8)/DAY(I8) -> 1 | J61: 15 | K61: 15 | L61: 30 | M61: 65 | N61: 30 | O61: 75 | P61: 10 | Q61: 35 | R61: 75 | S61: 30 | T61: 65 | U61: 60
A62: 7 | B62: 85 | C62: 69 | D62: 65 | E62: 63 | F62: 1 | G62: 0.66666667 | H62: 0.83333333 | I62: 1 | J62: 55 | K62: 75 | L62: 45 | M62: 20 | N62: 40 | O62: 30 | P62: 25 | Q62: 30 | R62: 70 | S62: 70 | T62: 30 | U62: 25
A63: 8 | B63: 70 | C63: 79 | D63: 56 | E63: 59 | F63: =MONTH(F10)/DAY(F10) -> 1 | G63: =MONTH(G10)/DAY(G10) -> 1 | H63: =MONTH(H10)/DAY(H10) -> 1 | I63: =MONTH(I10)/DAY(I10) -> 1 | J63: 30 | K63: 70 | L63: 70 | M63: 20 | N63: 20 | O63: 20 | P63: 15 | Q63: 15 | R63: 60 | S63: 35 | T63: 80 | U63: 65
A64: 9 | B64: 79 | C64: 71 | D64: 72 | E64: 67 | F64: =MONTH(F11)/DAY(F11) -> 1 | G64: =MONTH(G11)/DAY(G11) -> 0.83333333 | H64: =MONTH(H11)/DAY(H11) -> 0.83333333 | I64: =MONTH(I11)/DAY(I11) -> 0.83333333 | J64: 40 | K64: 65 | L64: 25 | M64: 5 | N64: 0 | O64: 35 | P64: 20 | Q64: 15 | R64: 25 | S64: 75 | T64: 25 | U64: 15
A65: 10 | B65: 110 | C65: 96 | D65: 92 | E65: 127 | F65: =MONTH(F12)/DAY(F12) -> 0.8 | G65: =MONTH(G12)/DAY(G12) -> 1 | H65: =MONTH(H12)/DAY(H12) -> 1 | I65: =MONTH(I12)/DAY(I12) -> 1 | J65: 30 | K65: 20 | L65: 15 | M65: 25 | N65: 60 | O65: 65 | P65: 70 | Q65: 60 | R65: 55 | S65: 35 | T65: 20 | U65: 30
A66: 11 | B66: 90 | C66: 106 | D66: 90 | E66: 80 | F66: =MONTH(F13)/DAY(F13) -> 0.83333333 | G66: =MONTH(G13)/DAY(G13) -> 0.83333333 | H66: =MONTH(H13)/DAY(H13) -> 1 | I66: =MONTH(I13)/DAY(I13) -> 1 | J66: 55 | K66: 65 | L66: 80 | M66: 70 | N66: 45 | O66: 35 | P66: 70 | Q66: 65 | R66: 70 | S66: 80 | T66: 85 | U66: 60
...

Sheet DATA COLLECTION NEW
B1: Tracking Score (Error in Px) | F1: Threat Response Score (Hits/Total) | J1: Frustration TLX | N1: Performance TLX | R1: Mental Demand TLX
A2: Participant | B2: VS-VS | C2: VS-VV | D2: VS-AV | E2: VS-AS | F2: VS-VS | G2: VS-VV | H2: VS-AV | I2: VS-AS | J2: VS-VS | K2: VS-VV | L2: VS-AV | M2: VS-AS | N2: VS-VS | O2: VS-VV | P2: VS-AV | Q2: VS-AS | R2: VS-VS | S2: VS-VV | T2: VS-AV | U2: VS-AS
A3: 1 | B3: 69 | C3: 56 | D3: 57 | E3: 56 | F3: 1 | G3: 0.66666667 | H3: 1 | I3: 0.8 | J3: 40 | K3: 50 | L3: 5 | M3: 35 | N3: 35 | O3: 45 | P3: 5 | Q3: 30 | R3: 30 | S3: 40 | T3: 15 | U3: 20
A4: 2 | B4: 79 | C4: 76 | D4: 63 | E4: 54 | F4: 1 | G4: 1 | H4: 0.83333333 | I4: 1 | J4: 0 | K4: 35 | L4: 25 | M4: 0 | N4: 20 | O4: 30 | P4: 35 | Q4: 5 | R4: 90 | S4: 90 | T4: 30 | U4: 35
A5: 3 | B5: 87 | C5: 98 | D5: 73 | E5: 76 | F5: 1 | G5: 0.66666667 | H5: 0.66666667 | I5: 1 | J5: 25 | K5: 25 | L5: 10 | M5: 5 | N5: 35 | O5: 65 | P5: 45 | Q5: 30 | R5: 35 | S5: 30 | T5: 25 | U5: 15
A6: 4 | B6: 103 | C6: 98 | D6: 80 | E6: 114 | F6: 1 | G6: 0.8 | H6: 1 | I6: 1 | J6: 15 | K6: 30 | L6: 0 | M6: 5 | N6: 55 | O6: 40 | P6: 80 | Q6: 45 | R6: 25 | S6: 30 | T6: 0 | U6: 10
A7: 5 | B7: 75 | C7: 60 | D7: 51 | E7: 57 | F7: 0.83333333 | G7: 0.8 | H7: 1 | I7: 0.66666667 | J7: 15 | K7: 5 | L7: 0 | M7: 0 | N7: 50 | O7: 20 | P7: 5 | Q7: 25 | R7: 60 | S7: 35 | T7: 10 | U7: 25
A8: 6 | B8: 63 | C8: 61 | D8: 45 | E8: 53 | F8: 1 | G8: 0.83333333 | H8: 1 | I8: 1 | J8: 15 | K8: 15 | L8: 30 | M8: 65 | N8: 30 | O8: 75 | P8: 10 | Q8: 35 | R8: 75 | S8: 30 | T8: 65 | U8: 60
A9: 7 | B9: 85 | C9: 69 | D9: 65 | E9: 63 | F9: 1 | G9: 0.66666667 | H9: 0.83333333 | I9: 1 | J9: 55 | K9: 75 | L9: 45 | M9: 20 | N9: 40 | O9: 30 | P9: 25 | Q9: 30 | R9: 70 | S9: 70 | T9: 30 | U9: 25
A10: 8 | B10: 70 | C10: 79 | D10: 56 | E10: 59 | F10: 1 | G10: 1 | H10: 1 | I10: 1 | J10: 30 | K10: 70 | L10: 70 | M10: 20 | N10: 20 | O10: 20 | P10: 15 | Q10: 15 | R10: 60 | S10: 35 | T10: 80 | U10: 65
A11: 9 | B11: 79 | C11: 71 | D11: 72 | E11: 67 | F11: 1 | G11: 0.83333333 | H11: 0.83333333 | I11: 0.83333333 | J11: 40 | K11: 65 | L11: 25 | M11: 5 | N11: 0 | O11: 35 | P11: 20 | Q11: 15 | R11: 25 | S11: 75 | T11: 25 | U11: 15
A12: 10 | B12: 110 | C12: 96 | D12: 92 | E12: 127 | F12: 0.8 | G12: 1 | H12: 1 | I12: 1 | J12: 30 | K12: 20 | L12: 15 | M12: 25 | N12: 60 | O12: 65 | P12: 70 | Q12: 60 | R12: 55 | S12: 35 | T12: 20 | U12: 30
A13: 11 | B13: 90 | C13: 106 | D13: 90 | E13: 80 | F13: 0.83333333 | G13: 0.83333333 | H13: 1 | I13: 1 | J13: 55 | K13: 65 | L13: 80 | M13: 70 | N13: 45 | O13: 35 | P13: 70 | Q13: 65 | R13: 70 | S13: 80 | T13: 85 | U13: 60
A14: 12 | B14: 62 | C14: 63 | D14: 92 | E14: 60 | F14: 1 | G14: 0.66666667 | H14: 1 | I14: 1 | J14: 45 | K14: 50 | L14: 40 | M14: 45 | N14: 25 | O14: 60 | P14: 40 | Q14: 30 | R14: 85 | S14: 90 | T14: 35 | U14: 30
... A42: 40 | B42: 59 | C42: 56 | D42: 55 | E42: 53 | F42: 1 | G42: 0.8 | H42: 1 | I42: 1 | J42: 20 | K42: 40 | L42: 30 | M42: 10 | N42: 20 | O42: 40 | P42: 30 | Q42: 20 | R42: 30 | S42: 40 | T42: 50 | U42: 20

Sheet ANOVA
A1: Participant | B1: Condition | C1: Modality | D1: Code | E1: Tracking Score | F1: Accuracy | G1: Frustration TLX | H1: Performance TLX | I1: Mental Demand TLX | J1: Combined TLX
A2: {=INDEX('Data Collection'!$A$3:$A$54, INT((ROW()-2)/4)+1)} -> 1 | B2: =INDEX({"VS-VS","VS-VV","VS-AV","VS-AS"}, MOD(ROW()-2,4)+1) -> VS-VS | C2: =IF(RIGHT(B2,2)="VS","Visual",IF(RIGHT(B2,2)="VV", "Visual",IF(RIGHT(B2,2)="AV","Auditory",IF(RIGHT(B2,2)="AS","Auditory")))) -> Visual | D2: =IF(RIGHT(B2,1)="S","Spatial",IF(RIGHT(B2,1)="V", "Verbal",IF(RIGHT(B2,1)="V","Verbal",IF(RIGHT(B2,1)="S","Spatial")))) -> Spatial | E2: {=INDEX('Data Collection'!$B$2:$E$54,MATCH(A2,'Data Collection'!$A$2:$A$54,0),MATCH(B2,'Data Collection'!$B$2:$E$2,0))} -> 69 | F2: {=IFERROR(_xludf.let(cell,INDEX('Data Collection'!$F$2:$I$54,MATCH(A2,'Data Collection'!$A$2:$A$54,0),MATCH(B2,'Data Collection'!$F$2:$I$2,0)),LEFT(cell, FIND("/", cell)-1) / MID(cell, FIND("/", cell)+1, LEN(cell))),"")} | G2: {=INDEX('Data Collection'!$J$2:$M$54,MATCH(A2,'Data Collection'!$A$2:$A$54,0),MATCH(B2,'Data Collection'!$J$2:$M$2,0))} -> 40 | H2: {=INDEX('Data Collection'!$N$2:$Q$54,MATCH(A2,'Data Collection'!$A$2:$A$54,0),MATCH(B2,'Data Collection'!$N$2:$Q$2,0))} -> 35 | I2: {=INDEX('Data Collection'!$R$2:$U$54,MATCH(A2,'Data Collection'!$A$2:$A$54,0),MATCH(B2,'Data Collection'!$R$2:$U$2,0))} -> 30 | J2: =IFERROR(AVERAGE(G2:I2),"") -> 35 | M2: Threat Response Score (Hits/Total)
A3: {=INDEX('Data Collection'!$A$3:$A$54, INT((ROW()-2)/4)+1)} -> 1 | B3: =INDEX({"VS-VS","VS-VV","VS-AV","VS-AS"}, MOD(ROW()-2,4)+1) -> VS-VV | C3: =IF(RIGHT(B3,2)="VS","Visual",IF(RIGHT(B3,2)="VV", "Visual",IF(RIGHT(B3,2)="AV","Auditory",IF(RIGHT(B3,2)="AS","Auditory")))) -> Visual | D3: =IF(RIGHT(B3,1)="S","Spatial",IF(RIGHT(B3,1)="V", "Verbal",IF(RIGHT(B3,1)="V","Verbal",IF(RIGHT(B3,1)="S","Spatial")))) -> Verbal | E3: {=INDEX('Data Collection'!$B$2:$E$54,MATCH(A3,'Data Collection'!$A$2:$A$54,0),MATCH(B3,'Data Collection'!$B$2:$E$2,0))} -> 56 | F3: {=IFERROR(_xludf.let(cell,INDEX('Data Collection'!$F$2:$I$54,MATCH(A3,'Data Collection'!$A$2:$A$54,0),MATCH(B3,'Data Collection'!$F$2:$I$2,0)),LEFT(cell, FIND("/", cell)-1) / MID(cell, FIND("/", cell)+1, LEN(cell))),"")} | G3: {=INDEX('Data Collection'!$J$2:$M$54,MATCH(A3,'Data Collection'!$A$2:$A$54,0),MATCH(B3,'Data Collection'!$J$2:$M$2,0))} -> 50 | H3: {=INDEX('Data Collection'!$N$2:$Q$54,MATCH(A3,'Data Collection'!$A$2:$A$54,0),MATCH(B3,'Data Collection'!$N$2:$Q$2,0))} -> 45 | I3: {=INDEX('Data Collection'!$R$2:$U$54,MATCH(A3,'Data Collection'!$A$2:$A$54,0),MATCH(B3,'Data Collection'!$R$2:$U$2,0))} -> 40 | J3: =IFERROR(AVERAGE(G3:I3),"") -> 45 | M3: VS-VS | N3: VS-VV | O3: VS-AV | P3: VS-AS
A4: {=INDEX('Data Collection'!$A$3:$A$54, INT((ROW()-2)/4)+1)} -> 1 | B4: =INDEX({"VS-VS","VS-VV","VS-AV","VS-AS"}, MOD(ROW()-2,4)+1) -> VS-AV | C4: =IF(RIGHT(B4,2)="VS","Visual",IF(RIGHT(B4,2)="VV", "Visual",IF(RIGHT(B4,2)="AV","Auditory",IF(RIGHT(B4,2)="AS","Auditory")))) -> Auditory | D4: =IF(RIGHT(B4,1)="S","Spatial",IF(RIGHT(B4,1)="V", "Verbal",IF(RIGHT(B4,1)="V","Verbal",IF(RIGHT(B4,1)="S","Spatial")))) -> Verbal | E4: {=INDEX('Data Collection'!$B$2:$E$54,MATCH(A4,'Data Collection'!$A$2:$A$54,0),MATCH(B4,'Data Collection'!$B$2:$E$2,0))} -> 57 | F4: {=IFERROR(_xludf.let(cell,INDEX('Data Collection'!$F$2:$I$54,MATCH(A4,'Data Collection'!$A$2:$A$54,0),MATCH(B4,'Data Collection'!$F$2:$I$2,0)),LEFT(cell, FIND("/", cell)-1) / MID(cell, FIND("/", cell)+1, LEN(cell))),"")} | G4: {=INDEX('Data Collection'!$J$2:$M$54,MATCH(A4,'Data Collection'!$A$2:$A$54,0),MATCH(B4,'Data Collection'!$J$2:$M$2,0))} -> 5 | H4: {=INDEX('Data Collection'!$N$2:$Q$54,MATCH(A4,'Data Collection'!$A$2:$A$54,0),MATCH(B4,'Data Collection'!$N$2:$Q$2,0))} -> 5 | I4: {=INDEX('Data Collection'!$R$2:$U$54,MATCH(A4,'Data Collection'!$A$2:$A$54,0),MATCH(B4,'Data Collection'!$R$2:$U$2,0))} -> 15 | J4: =IFERROR(AVERAGE(G4:I4),"") -> 8.3333333 | L4: Mean | M4: =IFERROR(__xludf.DUMMYFUNCTION("average(FILTER($F2:$F148,$B$2:$B$148=M3))"),0.926126126126126) -> 0.92612613 | N4: =IFERROR(__xludf.DUMMYFUNCTION("average(FILTER($F2:$F148,$B$2:$B$148=N3))"),0.863963963963964) -> 0.86396396 | O4: =IFERROR(__xludf.DUMMYFUNCTION("average(FILTER($F2:$F148,$B$2:$B$148=O3))"),0.89009009009009) -> 0.89009009 | P4: =IFERROR(__xludf.DUMMYFUNCTION("average(FILTER($F2:$F148,$B$2:$B$148=P3))"),0.923148148148147) -> 0.92314815
A5: {=INDEX('Data Collection'!$A$3:$A$54, INT((ROW()-2)/4)+1)} -> 1 | B5: =INDEX({"VS-VS","VS-VV","VS-AV","VS-AS"}, MOD(ROW()-2,4)+1) -> VS-AS | C5: =IF(RIGHT(B5,2)="VS","Visual",IF(RIGHT(B5,2)="VV", "Visual",IF(RIGHT(B5,2)="AV","Auditory",IF(RIGHT(B5,2)="AS","Auditory")))) -> Auditory | D5: =IF(RIGHT(B5,1)="S","Spatial",IF(RIGHT(B5,1)="V", "Verbal",IF(RIGHT(B5,1)="V","Verbal",IF(RIGHT(B5,1)="S","Spatial")))) -> Spatial | E5: {=INDEX('Data Collection'!$B$2:$E$54,MATCH(A5,'Data Collection'!$A$2:$A$54,0),MATCH(B5,'Data Collection'!$B$2:$E$2,0))} -> 56 | F5: {=IFERROR(_xludf.let(cell,INDEX('Data Collection'!$F$2:$I$54,MATCH(A5,'Data Collection'!$A$2:$A$54,0),MATCH(B5,'Data Collection'!$F$2:$I$2,0)),LEFT(cell, FIND("/", cell)-1) / MID(cell, FIND("/", cell)+1, LEN(cell))),"")} | G5: {=INDEX('Data Collection'!$J$2:$M$54,MATCH(A5,'Data Collection'!$A$2:$A$54,0),MATCH(B5,'Data Collection'!$J$2:$M$2,0))} -> 35 | H5: {=INDEX('Data Collection'!$N$2:$Q$54,MATCH(A5,'Data Collection'!$A$2:$A$54,0),MATCH(B5,'Data Collection'!$N$2:$Q$2,0))} -> 30 | I5: {=INDEX('Data Collection'!$R$2:$U$54,MATCH(A5,'Data Collection'!$A$2:$A$54,0),MATCH(B5,'Data Collection'!$R$2:$U$2,0))} -> 20 | J5: =IFERROR(AVERAGE(G5:I5),"") -> 28.333333 | L5: Std Dev | M5: =IFERROR(__xludf.DUMMYFUNCTION("STDEV(FILTER($F2:$F148,$B$2:$B$148=M3))"),0.123011375348509) -> 0.12301138 | N5: =IFERROR(__xludf.DUMMYFUNCTION("STDEV(FILTER($F2:$F148,$B$2:$B$148=N3))"),0.127506566855428) -> 0.12750657 | O5: =IFERROR(__xludf.DUMMYFUNCTION("STDEV(FILTER($F2:$F148,$B$2:$B$148=O3))"),0.138302063593163) -> 0.13830206 | P5: =IFERROR(__xludf.DUMMYFUNCTION("STDEV(FILTER($F2:$F148,$B$2:$B$148=P3))"),0.0962204626108401) -> 0.096220463
A6: {=INDEX('Data Collection'!$A$3:$A$54, INT((ROW()-2)/4)+1)} -> 2 | B6: =INDEX({"VS-VS","VS-VV","VS-AV","VS-AS"}, MOD(ROW()-2,4)+1) -> VS-VS | C6: =IF(RIGHT(B6,2)="VS","Visual",IF(RIGHT(B6,2)="VV", "Visual",IF(RIGHT(B6,2)="AV","Auditory",IF(RIGHT(B6,2)="AS","Auditory")))) -> Visual | D6: =IF(RIGHT(B6,1)="S","Spatial",IF(RIGHT(B6,1)="V", "Verbal",IF(RIGHT(B6,1)="V","Verbal",IF(RIGHT(B6,1)="S","Spatial")))) -> Spatial | E6: {=INDEX('Data Collection'!$B$2:$E$54,MATCH(A6,'Data Collection'!$A$2:$A$54,0),MATCH(B6,'Data Collection'!$B$2:$E$2,0))} -> 79 | F6: {=IFERROR(_xludf.let(cell,INDEX('Data Collection'!$F$2:$I$54,MATCH(A6,'Data Collection'!$A$2:$A$54,0),MATCH(B6,'Data Collection'!$F$2:$I$2,0)),LEFT(cell, FIND("/", cell)-1) / MID(cell, FIND("/", cell)+1, LEN(cell))),"")} | G6: {=INDEX('Data Collection'!$J$2:$M$54,MATCH(A6,'Data Collection'!$A$2:$A$54,0),MATCH(B6,'Data Collection'!$J$2:$M$2,0))} -> 0 | H6: {=INDEX('Data Collection'!$N$2:$Q$54,MATCH(A6,'Data Collection'!$A$2:$A$54,0),MATCH(B6,'Data Collection'!$N$2:$Q$2,0))} -> 20 | I6: {=INDEX('Data Collection'!$R$2:$U$54,MATCH(A6,'Data Collection'!$A$2:$A$54,0),MATCH(B6,'Data Collection'!$R$2:$U$2,0))} -> 90 | J6: =IFERROR(AVERAGE(G6:I6),"") -> 36.666667
A7: {=INDEX('Data Collection'!$A$3:$A$54, INT((ROW()-2)/4)+1)} -> 2 | B7: =INDEX({"VS-VS","VS-VV","VS-AV","VS-AS"}, MOD(ROW()-2,4)+1) -> VS-VV | C7: =IF(RIGHT(B7,2)="VS","Visual",IF(RIGHT(B7,2)="VV", "Visual",IF(RIGHT(B7,2)="AV","Auditory",IF(RIGHT(B7,2)="AS","Auditory")))) -> Visual | D7: =IF(RIGHT(B7,1)="S","Spatial",IF(RIGHT(B7,1)="V", "Verbal",IF(RIGHT(B7,1)="V","Verbal",IF(RIGHT(B7,1)="S","Spatial")))) -> Verbal | E7: {=INDEX('Data Collection'!$B$2:$E$54,MATCH(A7,'Data Collection'!$A$2:$A$54,0),MATCH(B7,'Data Collection'!$B$2:$E$2,0))} -> 76 | F7: {=IFERROR(_xludf.let(cell,INDEX('Data Collection'!$F$2:$I$54,MATCH(A7,'Data Collection'!$A$2:$A$54,0),MATCH(B7,'Data Collection'!$F$2:$I$2,0)),LEFT(cell, FIND("/", cell)-1) / MID(cell, FIND("/", cell)+1, LEN(cell))),"")} | G7: {=INDEX('Data Collection'!$J$2:$M$54,MATCH(A7,'Data Collection'!$A$2:$A$54,0),MATCH(B7,'Data Collection'!$J$2:$M$2,0))} -> 35 | H7: {=INDEX('Data Collection'!$N$2:$Q$54,MATCH(A7,'Data Collection'!$A$2:$A$54,0),MATCH(B7,'Data Collection'!$N$2:$Q$2,0))} -> 30 | I7: {=INDEX('Data Collection'!$R$2:$U$54,MATCH(A7,'Data Collection'!$A$2:$A$54,0),MATCH(B7,'Data Collection'!$R$2:$U$2,0))} -> 90 | J7: =IFERROR(AVERAGE(G7:I7),"") -> 51.666667
A8: {=INDEX('Data Collection'!$A$3:$A$54, INT((ROW()-2)/4)+1)} -> 2 | B8: =INDEX({"VS-VS","VS-VV","VS-AV","VS-AS"}, MOD(ROW()-2,4)+1) -> VS-AV | C8: =IF(RIGHT(B8,2)="VS","Visual",IF(RIGHT(B8,2)="VV", "Visual",IF(RIGHT(B8,2)="AV","Auditory",IF(RIGHT(B8,2)="AS","Auditory")))) -> Auditory | D8: =IF(RIGHT(B8,1)="S","Spatial",IF(RIGHT(B8,1)="V", "Verbal",IF(RIGHT(B8,1)="V","Verbal",IF(RIGHT(B8,1)="S","Spatial")))) -> Verbal | E8: {=INDEX('Data Collection'!$B$2:$E$54,MATCH(A8,'Data Collection'!$A$2:$A$54,0),MATCH(B8,'Data Collection'!$B$2:$E$2,0))} -> 63 | F8: {=IFERROR(_xludf.let(cell,INDEX('Data Collection'!$F$2:$I$54,MATCH(A8,'Data Collection'!$A$2:$A$54,0),MATCH(B8,'Data Collection'!$F$2:$I$2,0)),LEFT(cell, FIND("/", cell)-1) / MID(cell, FIND("/", cell)+1, LEN(cell))),"")} | G8: {=INDEX('Data Collection'!$J$2:$M$54,MATCH(A8,'Data Collection'!$A$2:$A$54,0),MATCH(B8,'Data Collection'!$J$2:$M$2,0))} -> 25 | H8: {=INDEX('Data Collection'!$N$2:$Q$54,MATCH(A8,'Data Collection'!$A$2:$A$54,0),MATCH(B8,'Data Collection'!$N$2:$Q$2,0))} -> 35 | I8: {=INDEX('Data Collection'!$R$2:$U$54,MATCH(A8,'Data Collection'!$A$2:$A$54,0),MATCH(B8,'Data Collection'!$R$2:$U$2,0))} -> 30 | J8: =IFERROR(AVERAGE(G8:I8),"") -> 30
A9: {=INDEX('Data Collection'!$A$3:$A$54, INT((ROW()-2)/4)+1)} -> 2 | B9: =INDEX({"VS-VS","VS-VV","VS-AV","VS-AS"}, MOD(ROW()-2,4)+1) -> VS-AS | C9: =IF(RIGHT(B9,2)="VS","Visual",IF(RIGHT(B9,2)="VV", "Visual",IF(RIGHT(B9,2)="AV","Auditory",IF(RIGHT(B9,2)="AS","Auditory")))) -> Auditory | D9: =IF(RIGHT(B9,1)="S","Spatial",IF(RIGHT(B9,1)="V", "Verbal",IF(RIGHT(B9,1)="V","Verbal",IF(RIGHT(B9,1)="S","Spatial")))) -> Spatial | E9: {=INDEX('Data Collection'!$B$2:$E$54,MATCH(A9,'Data Collection'!$A$2:$A$54,0),MATCH(B9,'Data Collection'!$B$2:$E$2,0))} -> 54 | F9: {=IFERROR(_xludf.let(cell,INDEX('Data Collection'!$F$2:$I$54,MATCH(A9,'Data Collection'!$A$2:$A$54,0),MATCH(B9,'Data Collection'!$F$2:$I$2,0)),LEFT(cell, FIND("/", cell)-1) / MID(cell, FIND("/", cell)+1, LEN(cell))),"")} | G9: {=INDEX('Data Collection'!$J$2:$M$54,MATCH(A9,'Data Collection'!$A$2:$A$54,0),MATCH(B9,'Data Collection'!$J$2:$M$2,0))} -> 0 | H9: {=INDEX('Data Collection'!$N$2:$Q$54,MATCH(A9,'Data Collection'!$A$2:$A$54,0),MATCH(B9,'Data Collection'!$N$2:$Q$2,0))} -> 5 | I9: {=INDEX('Data Collection'!$R$2:$U$54,MATCH(A9,'Data Collection'!$A$2:$A$54,0),MATCH(B9,'Data Collection'!$R$2:$U$2,0))} -> 35 | J9: =IFERROR(AVERAGE(G9:I9),"") -> 13.333333
A10: {=INDEX('Data Collection'!$A$3:$A$54, INT((ROW()-2)/4)+1)} -> 3 | B10: =INDEX({"VS-VS","VS-VV","VS-AV","VS-AS"}, MOD(ROW()-2,4)+1) -> VS-VS | C10: =IF(RIGHT(B10,2)="VS","Visual",IF(RIGHT(B10,2)="VV", "Visual",IF(RIGHT(B10,2)="AV","Auditory",IF(RIGHT(B10,2)="AS","Auditory")))) -> Visual | D10: =IF(RIGHT(B10,1)="S","Spatial",IF(RIGHT(B10,1)="V", "Verbal",IF(RIGHT(B10,1)="V","Verbal",IF(RIGHT(B10,1)="S","Spatial")))) -> Spatial | E10: {=INDEX('Data Collection'!$B$2:$E$54,MATCH(A10,'Data Collection'!$A$2:$A$54,0),MATCH(B10,'Data Collection'!$B$2:$E$2,0))} -> 87 | F10: {=IFERROR(_xludf.let(cell,INDEX('Data Collection'!$F$2:$I$54,MATCH(A10,'Data Collection'!$A$2:$A$54,0),MATCH(B10,'Data Collection'!$F$2:$I$2,0)),LEFT(cell, FIND("/", cell)-1) / MID(cell, FIND("/", cell)+1, LEN(cell))),"")} | G10: {=INDEX('Data Collection'!$J$2:$M$54,MATCH(A10,'Data Collection'!$A$2:$A$54,0),MATCH(B10,'Data Collection'!$J$2:$M$2,0))} -> 25 | H10: {=INDEX('Data Collection'!$N$2:$Q$54,MATCH(A10,'Data Collection'!$A$2:$A$54,0),MATCH(B10,'Data Collection'!$N$2:$Q$2,0))} -> 35 | I10: {=INDEX('Data Collection'!$R$2:$U$54,MATCH(A10,'Data Collection'!$A$2:$A$54,0),MATCH(B10,'Data Collection'!$R$2:$U$2,0))} -> 35 | J10: =IFERROR(AVERAGE(G10:I10),"") -> 31.666667
A11: {=INDEX('Data Collection'!$A$3:$A$54, INT((ROW()-2)/4)+1)} -> 3 | B11: =INDEX({"VS-VS","VS-VV","VS-AV","VS-AS"}, MOD(ROW()-2,4)+1) -> VS-VV | C11: =IF(RIGHT(B11,2)="VS","Visual",IF(RIGHT(B11,2)="VV", "Visual",IF(RIGHT(B11,2)="AV","Auditory",IF(RIGHT(B11,2)="AS","Auditory")))) -> Visual | D11: =IF(RIGHT(B11,1)="S","Spatial",IF(RIGHT(B11,1)="V", "Verbal",IF(RIGHT(B11,1)="V","Verbal",IF(RIGHT(B11,1)="S","Spatial")))) -> Verbal | E11: {=INDEX('Data Collection'!$B$2:$E$54,MATCH(A11,'Data Collection'!$A$2:$A$54,0),MATCH(B11,'Data Collection'!$B$2:$E$2,0))} -> 98 | F11: {=IFERROR(_xludf.let(cell,INDEX('Data Collection'!$F$2:$I$54,MATCH(A11,'Data Collection'!$A$2:$A$54,0),MATCH(B11,'Data Collection'!$F$2:$I$2,0)),LEFT(cell, FIND("/", cell)-1) / MID(cell, FIND("/", cell)+1, LEN(cell))),"")} | G11: {=INDEX('Data Collection'!$J$2:$M$54,MATCH(A11,'Data Collection'!$A$2:$A$54,0),MATCH(B11,'Data Collection'!$J$2:$M$2,0))} -> 25 | H11: {=INDEX('Data Collection'!$N$2:$Q$54,MATCH(A11,'Data Collection'!$A$2:$A$54,0),MATCH(B11,'Data Collection'!$N$2:$Q$2,0))} -> 65 | I11: {=INDEX('Data Collection'!$R$2:$U$54,MATCH(A11,'Data Collection'!$A$2:$A$54,0),MATCH(B11,'Data Collection'!$R$2:$U$2,0))} -> 30 | J11: =IFERROR(AVERAGE(G11:I11),"") -> 40
A12: {=INDEX('Data Collection'!$A$3:$A$54, INT((ROW()-2)/4)+1)} -> 3 | B12: =INDEX({"VS-VS","VS-VV","VS-AV","VS-AS"}, MOD(ROW()-2,4)+1) -> VS-AV | C12: =IF(RIGHT(B12,2)="VS","Visual",IF(RIGHT(B12,2)="VV", "Visual",IF(RIGHT(B12,2)="AV","Auditory",IF(RIGHT(B12,2)="AS","Auditory")))) -> Auditory | D12: =IF(RIGHT(B12,1)="S","Spatial",IF(RIGHT(B12,1)="V", "Verbal",IF(RIGHT(B12,1)="V","Verbal",IF(RIGHT(B12,1)="S","Spatial")))) -> Verbal | E12: {=INDEX('Data Collection'!$B$2:$E$54,MATCH(A12,'Data Collection'!$A$2:$A$54,0),MATCH(B12,'Data Collection'!$B$2:$E$2,0))} -> 73 | F12: {=IFERROR(_xludf.let(cell,INDEX('Data Collection'!$F$2:$I$54,MATCH(A12,'Data Collection'!$A$2:$A$54,0),MATCH(B12,'Data Collection'!$F$2:$I$2,0)),LEFT(cell, FIND("/", cell)-1) / MID(cell, FIND("/", cell)+1, LEN(cell))),"")} | G12: {=INDEX('Data Collection'!$J$2:$M$54,MATCH(A12,'Data Collection'!$A$2:$A$54,0),MATCH(B12,'Data Collection'!$J$2:$M$2,0))} -> 10 | H12: {=INDEX('Data Collection'!$N$2:$Q$54,MATCH(A12,'Data Collection'!$A$2:$A$54,0),MATCH(B12,'Data Collection'!$N$2:$Q$2,0))} -> 45 | I12: {=INDEX('Data Collection'!$R$2:$U$54,MATCH(A12,'Data Collection'!$A$2:$A$54,0),MATCH(B12,'Data Collection'!$R$2:$U$2,0))} -> 25 | J12: =IFERROR(AVERAGE(G12:I12),"") -> 26.666667
A13: {=INDEX('Data Collection'!$A$3:$A$54, INT((ROW()-2)/4)+1)} -> 3 | B13: =INDEX({"VS-VS","VS-VV","VS-AV","VS-AS"}, MOD(ROW()-2,4)+1) -> VS-AS | C13: =IF(RIGHT(B13,2)="VS","Visual",IF(RIGHT(B13,2)="VV", "Visual",IF(RIGHT(B13,2)="AV","Auditory",IF(RIGHT(B13,2)="AS","Auditory")))) -> Auditory | D13: =IF(RIGHT(B13,1)="S","Spatial",IF(RIGHT(B13,1)="V", "Verbal",IF(RIGHT(B13,1)="V","Verbal",IF(RIGHT(B13,1)="S","Spatial")))) -> Spatial | E13: {=INDEX('Data Collection'!$B$2:$E$54,MATCH(A13,'Data Collection'!$A$2:$A$54,0),MATCH(B13,'Data Collection'!$B$2:$E$2,0))} -> 76 | F13: {=IFERROR(_xludf.let(cell,INDEX('Data Collection'!$F$2:$I$54,MATCH(A13,'Data Collection'!$A$2:$A$54,0),MATCH(B13,'Data Collection'!$F$2:$I$2,0)),LEFT(cell, FIND("/", cell)-1) / MID(cell, FIND("/", cell)+1, LEN(cell))),"")} | G13: {=INDEX('Data Collection'!$J$2:$M$54,MATCH(A13,'Data Collection'!$A$2:$A$54,0),MATCH(B13,'Data Collection'!$J$2:$M$2,0))} -> 5 | H13: {=INDEX('Data Collection'!$N$2:$Q$54,MATCH(A13,'Data Collection'!$A$2:$A$54,0),MATCH(B13,'Data Collection'!$N$2:$Q$2,0))} -> 30 | I13: {=INDEX('Data Collection'!$R$2:$U$54,MATCH(A13,'Data Collection'!$A$2:$A$54,0),MATCH(B13,'Data Collection'!$R$2:$U$2,0))} -> 15 | J13: =IFERROR(AVERAGE(G13:I13),"") -> 16.666667
A14: {=INDEX('Data Collection'!$A$3:$A$54, INT((ROW()-2)/4)+1)} -> 4 | B14: =INDEX({"VS-VS","VS-VV","VS-AV","VS-AS"}, MOD(ROW()-2,4)+1) -> VS-VS | C14: =IF(RIGHT(B14,2)="VS","Visual",IF(RIGHT(B14,2)="VV", "Visual",IF(RIGHT(B14,2)="AV","Auditory",IF(RIGHT(B14,2)="AS","Auditory")))) -> Visual | D14: =IF(RIGHT(B14,1)="S","Spatial",IF(RIGHT(B14,1)="V", "Verbal",IF(RIGHT(B14,1)="V","Verbal",IF(RIGHT(B14,1)="S","Spatial")))) -> Spatial | E14: {=INDEX('Data Collection'!$B$2:$E$54,MATCH(A14,'Data Collection'!$A$2:$A$54,0),MATCH(B14,'Data Collection'!$B$2:$E$2,0))} -> 103 | F14: {=IFERROR(_xludf.let(cell,INDEX('Data Collection'!$F$2:$I$54,MATCH(A14,'Data Collection'!$A$2:$A$54,0),MATCH(B14,'Data Collection'!$F$2:$I$2,0)),LEFT(cell, FIND("/", cell)-1) / MID(cell, FIND("/", cell)+1, LEN(cell))),"")} | G14: {=INDEX('Data Collection'!$J$2:$M$54,MATCH(A14,'Data Collection'!$A$2:$A$54,0),MATCH(B14,'Data Collection'!$J$2:$M$2,0))} -> 15 | H14: {=INDEX('Data Collection'!$N$2:$Q$54,MATCH(A14,'Data Collection'!$A$2:$A$54,0),MATCH(B14,'Data Collection'!$N$2:$Q$2,0))} -> 55 | I14: {=INDEX('Data Collection'!$R$2:$U$54,MATCH(A14,'Data Collection'!$A$2:$A$54,0),MATCH(B14,'Data Collection'!$R$2:$U$2,0))} -> 25 | J14: =IFERROR(AVERAGE(G14:I14),"") -> 31.666667
A15: {=INDEX('Data Collection'!$A$3:$A$54, INT((ROW()-2)/4)+1)} -> 4 | B15: =INDEX({"VS-VS","VS-VV","VS-AV","VS-AS"}, MOD(ROW()-2,4)+1) -> VS-VV | C15: =IF(RIGHT(B15,2)="VS","Visual",IF(RIGHT(B15,2)="VV", "Visual",IF(RIGHT(B15,2)="AV","Auditory",IF(RIGHT(B15,2)="AS","Auditory")))) -> Visual | D15: =IF(RIGHT(B15,1)="S","Spatial",IF(RIGHT(B15,1)="V", "Verbal",IF(RIGHT(B15,1)="V","Verbal",IF(RIGHT(B15,1)="S","Spatial")))) -> Verbal | E15: {=INDEX('Data Collection'!$B$2:$E$54,MATCH(A15,'Data Collection'!$A$2:$A$54,0),MATCH(B15,'Data Collection'!$B$2:$E$2,0))} -> 98 | F15: {=IFERROR(_xludf.let(cell,INDEX('Data Collection'!$F$2:$I$54,MATCH(A15,'Data Collection'!$A$2:$A$54,0),MATCH(B15,'Data Collection'!$F$2:$I$2,0)),LEFT(cell, FIND("/", cell)-1) / MID(cell, FIND("/", cell)+1, LEN(cell))),"")} | G15: {=INDEX('Data Collection'!$J$2:$M$54,MATCH(A15,'Data Collection'!$A$2:$A$54,0),MATCH(B15,'Data Collection'!$J$2:$M$2,0))} -> 30 | H15: {=INDEX('Data Collection'!$N$2:$Q$54,MATCH(A15,'Data Collection'!$A$2:$A$54,0),MATCH(B15,'Data Collection'!$N$2:$Q$2,0))} -> 40 | I15: {=INDEX('Data Collection'!$R$2:$U$54,MATCH(A15,'Data Collection'!$A$2:$A$54,0),MATCH(B15,'Data Collection'!$R$2:$U$2,0))} -> 30 | J15: =IFERROR(AVERAGE(G15:I15),"") -> 33.333333
A16: {=INDEX('Data Collection'!$A$3:$A$54, INT((ROW()-2)/4)+1)} -> 4 | B16: =INDEX({"VS-VS","VS-VV","VS-AV","VS-AS"}, MOD(ROW()-2,4)+1) -> VS-AV | C16: =IF(RIGHT(B16,2)="VS","Visual",IF(RIGHT(B16,2)="VV", "Visual",IF(RIGHT(B16,2)="AV","Auditory",IF(RIGHT(B16,2)="AS","Auditory")))) -> Auditory | D16: =IF(RIGHT(B16,1)="S","Spatial",IF(RIGHT(B16,1)="V", "Verbal",IF(RIGHT(B16,1)="V","Verbal",IF(RIGHT(B16,1)="S","Spatial")))) -> Verbal | E16: {=INDEX('Data Collection'!$B$2:$E$54,MATCH(A16,'Data Collection'!$A$2:$A$54,0),MATCH(B16,'Data Collection'!$B$2:$E$2,0))} -> 80 | F16: {=IFERROR(_xludf.let(cell,INDEX('Data Collection'!$F$2:$I$54,MATCH(A16,'Data Collection'!$A$2:$A$54,0),MATCH(B16,'Data Collection'!$F$2:$I$2,0)),LEFT(cell, FIND("/", cell)-1) / MID(cell, FIND("/", cell)+1, LEN(cell))),"")} | G16: {=INDEX('Data Collection'!$J$2:$M$54,MATCH(A16,'Data Collection'!$A$2:$A$54,0),MATCH(B16,'Data Collection'!$J$2:$M$2,0))} -> 0 | H16: {=INDEX('Data Collection'!$N$2:$Q$54,MATCH(A16,'Data Collection'!$A$2:$A$54,0),MATCH(B16,'Data Collection'!$N$2:$Q$2,0))} -> 80 | I16: {=INDEX('Data Collection'!$R$2:$U$54,MATCH(A16,'Data Collection'!$A$2:$A$54,0),MATCH(B16,'Data Collection'!$R$2:$U$2,0))} -> 0 | J16: =IFERROR(AVERAGE(G16:I16),"") -> 26.666667
A17: {=INDEX('Data Collection'!$A$3:$A$54, INT((ROW()-2)/4)+1)} -> 4 | B17: =INDEX({"VS-VS","VS-VV","VS-AV","VS-AS"}, MOD(ROW()-2,4)+1) -> VS-AS | C17: =IF(RIGHT(B17,2)="VS","Visual",IF(RIGHT(B17,2)="VV", "Visual",IF(RIGHT(B17,2)="AV","Auditory",IF(RIGHT(B17,2)="AS","Auditory")))) -> Auditory | D17: =IF(RIGHT(B17,1)="S","Spatial",IF(RIGHT(B17,1)="V", "Verbal",IF(RIGHT(B17,1)="V","Verbal",IF(RIGHT(B17,1)="S","Spatial")))) -> Spatial | E17: {=INDEX('Data Collection'!$B$2:$E$54,MATCH(A17,'Data Collection'!$A$2:$A$54,0),MATCH(B17,'Data Collection'!$B$2:$E$2,0))} -> 114 | F17: {=IFERROR(_xludf.let(cell,INDEX('Data Collection'!$F$2:$I$54,MATCH(A17,'Data Collection'!$A$2:$A$54,0),MATCH(B17,'Data Collection'!$F$2:$I$2,0)),LEFT(cell, FIND("/", cell)-1) / MID(cell, FIND("/", cell)+1, LEN(cell))),"")} | G17: {=INDEX('Data Collection'!$J$2:$M$54,MATCH(A17,'Data Collection'!$A$2:$A$54,0),MATCH(B17,'Data Collection'!$J$2:$M$2,0))} -> 5 | H17: {=INDEX('Data Collection'!$N$2:$Q$54,MATCH(A17,'Data Collection'!$A$2:$A$54,0),MATCH(B17,'Data Collection'!$N$2:$Q$2,0))} -> 45 | I17: {=INDEX('Data Collection'!$R$2:$U$54,MATCH(A17,'Data Collection'!$A$2:$A$54,0),MATCH(B17,'Data Collection'!$R$2:$U$2,0))} -> 10 | J17: =IFERROR(AVERAGE(G17:I17),"") -> 20
... A161: {=INDEX('Data Collection'!$A$3:$A$54, INT((ROW()-2)/4)+1)} -> 40 | B161: =INDEX({"VS-VS","VS-VV","VS-AV","VS-AS"}, MOD(ROW()-2,4)+1) -> VS-AS | C161: =IF(RIGHT(B161,2)="VS","Visual",IF(RIGHT(B161,2)="VV", "Visual",IF(RIGHT(B161,2)="AV","Auditory",IF(RIGHT(B161,2)="AS","Auditory")))) -> Auditory | D161: =IF(RIGHT(B161,1)="S","Spatial",IF(RIGHT(B161,1)="V", "Verbal",IF(RIGHT(B161,1)="V","Verbal",IF(RIGHT(B161,1)="S","Spatial")))) -> Spatial | E161: {=INDEX('Data Collection'!$B$2:$E$54,MATCH(A161,'Data Collection'!$A$2:$A$54,0),MATCH(B161,'Data Collection'!$B$2:$E$2,0))} -> 53 | F161: {=IFERROR(_xludf.let(cell,INDEX('Data Collection'!$F$2:$I$54,MATCH(A161,'Data Collection'!$A$2:$A$54,0),MATCH(B161,'Data Collection'!$F$2:$I$2,0)),LEFT(cell, FIND("/", cell)-1) / MID(cell, FIND("/", cell)+1, LEN(cell))),"")} | G161: {=INDEX('Data Collection'!$J$2:$M$54,MATCH(A161,'Data Collection'!$A$2:$A$54,0),MATCH(B161,'Data Collection'!$J$2:$M$2,0))} -> 10 | H161: {=INDEX('Data Collection'!$N$2:$Q$54,MATCH(A161,'Data Collection'!$A$2:$A$54,0),MATCH(B161,'Data Collection'!$N$2:$Q$2,0))} -> 20 | I161: {=INDEX('Data Collection'!$R$2:$U$54,MATCH(A161,'Data Collection'!$A$2:$A$54,0),MATCH(B161,'Data Collection'!$R$2:$U$2,0))} -> 20 | J161: =IFERROR(AVERAGE(G161:I161),"") -> 16.666667
A162: {=INDEX('Data Collection'!$A$3:$A$54, INT((ROW()-2)/4)+1)} -> 41 | B162: =INDEX({"VS-VS","VS-VV","VS-AV","VS-AS"}, MOD(ROW()-2,4)+1) -> VS-VS | C162: =IF(RIGHT(B162,2)="VS","Visual",IF(RIGHT(B162,2)="VV", "Visual",IF(RIGHT(B162,2)="AV","Auditory",IF(RIGHT(B162,2)="AS","Auditory")))) -> Visual | D162: =IF(RIGHT(B162,1)="S","Spatial",IF(RIGHT(B162,1)="V", "Verbal",IF(RIGHT(B162,1)="V","Verbal",IF(RIGHT(B162,1)="S","Spatial")))) -> Spatial | E162: {=INDEX('Data Collection'!$B$2:$E$54,MATCH(A162,'Data Collection'!$A$2:$A$54,0),MATCH(B162,'Data Collection'!$B$2:$E$2,0))} -> 0 | F162: {=IFERROR(_xludf.let(cell,INDEX('Data Collection'!$F$2:$I$54,MATCH(A162,'Data Collection'!$A$2:$A$54,0),MATCH(B162,'Data Collection'!$F$2:$I$2,0)),LEFT(cell, FIND("/", cell)-1) / MID(cell, FIND("/", cell)+1, LEN(cell))),"")} | J162: =IFERROR(AVERAGE(G162:I162),"")
A163: {=INDEX('Data Collection'!$A$3:$A$54, INT((ROW()-2)/4)+1)} -> 41 | B163: =INDEX({"VS-VS","VS-VV","VS-AV","VS-AS"}, MOD(ROW()-2,4)+1) -> VS-VV | C163: =IF(RIGHT(B163,2)="VS","Visual",IF(RIGHT(B163,2)="VV", "Visual",IF(RIGHT(B163,2)="AV","Auditory",IF(RIGHT(B163,2)="AS","Auditory")))) -> Visual | D163: =IF(RIGHT(B163,1)="S","Spatial",IF(RIGHT(B163,1)="V", "Verbal",IF(RIGHT(B163,1)="V","Verbal",IF(RIGHT(B163,1)="S","Spatial")))) -> Verbal | E163: {=INDEX('Data Collection'!$B$2:$E$54,MATCH(A163,'Data Collection'!$A$2:$A$54,0),MATCH(B163,'Data Collection'!$B$2:$E$2,0))} -> 0 | F163: {=IFERROR(_xludf.let(cell,INDEX('Data Collection'!$F$2:$I$54,MATCH(A163,'Data Collection'!$A$2:$A$54,0),MATCH(B163,'Data Collection'!$F$2:$I$2,0)),LEFT(cell, FIND("/", cell)-1) / MID(cell, FIND("/", cell)+1, LEN(cell))),"")} | J163: =IFERROR(AVERAGE(G163:I163),"")
A164: {=INDEX('Data Collection'!$A$3:$A$54, INT((ROW()-2)/4)+1)} -> 41 | B164: =INDEX({"VS-VS","VS-VV","VS-AV","VS-AS"}, MOD(ROW()-2,4)+1) -> VS-AV | C164: =IF(RIGHT(B164,2)="VS","Visual",IF(RIGHT(B164,2)="VV", "Visual",IF(RIGHT(B164,2)="AV","Auditory",IF(RIGHT(B164,2)="AS","Auditory")))) -> Auditory | D164: =IF(RIGHT(B164,1)="S","Spatial",IF(RIGHT(B164,1)="V", "Verbal",IF(RIGHT(B164,1)="V","Verbal",IF(RIGHT(B164,1)="S","Spatial")))) -> Verbal | E164: {=INDEX('Data Collection'!$B$2:$E$54,MATCH(A164,'Data Collection'!$A$2:$A$54,0),MATCH(B164,'Data Collection'!$B$2:$E$2,0))} -> 0 | F164: {=IFERROR(_xludf.let(cell,INDEX('Data Collection'!$F$2:$I$54,MATCH(A164,'Data Collection'!$A$2:$A$54,0),MATCH(B164,'Data Collection'!$F$2:$I$2,0)),LEFT(cell, FIND("/", cell)-1) / MID(cell, FIND("/", cell)+1, LEN(cell))),"")} | J164: =IFERROR(AVERAGE(G164:I164),"")
A165: {=INDEX('Data Collection'!$A$3:$A$54, INT((ROW()-2)/4)+1)} -> 41 | B165: =INDEX({"VS-VS","VS-VV","VS-AV","VS-AS"}, MOD(ROW()-2,4)+1) -> VS-AS | C165: =IF(RIGHT(B165,2)="VS","Visual",IF(RIGHT(B165,2)="VV", "Visual",IF(RIGHT(B165,2)="AV","Auditory",IF(RIGHT(B165,2)="AS","Auditory")))) -> Auditory | D165: =IF(RIGHT(B165,1)="S","Spatial",IF(RIGHT(B165,1)="V", "Verbal",IF(RIGHT(B165,1)="V","Verbal",IF(RIGHT(B165,1)="S","Spatial")))) -> Spatial | E165: {=INDEX('Data Collection'!$B$2:$E$54,MATCH(A165,'Data Collection'!$A$2:$A$54,0),MATCH(B165,'Data Collection'!$B$2:$E$2,0))} -> 0 | F165: {=IFERROR(_xludf.let(cell,INDEX('Data Collection'!$F$2:$I$54,MATCH(A165,'Data Collection'!$A$2:$A$54,0),MATCH(B165,'Data Collection'!$F$2:$I$2,0)),LEFT(cell, FIND("/", cell)-1) / MID(cell, FIND("/", cell)+1, LEN(cell))),"")} | J165: =IFERROR(AVERAGE(G165:I165),"")
A166: {=INDEX('Data Collection'!$A$3:$A$54, INT((ROW()-2)/4)+1)} -> 42 | B166: =INDEX({"VS-VS","VS-VV","VS-AV","VS-AS"}, MOD(ROW()-2,4)+1) -> VS-VS | C166: =IF(RIGHT(B166,2)="VS","Visual",IF(RIGHT(B166,2)="VV", "Visual",IF(RIGHT(B166,2)="AV","Auditory",IF(RIGHT(B166,2)="AS","Auditory")))) -> Visual | D166: =IF(RIGHT(B166,1)="S","Spatial",IF(RIGHT(B166,1)="V", "Verbal",IF(RIGHT(B166,1)="V","Verbal",IF(RIGHT(B166,1)="S","Spatial")))) -> Spatial | E166: {=INDEX('Data Collection'!$B$2:$E$54,MATCH(A166,'Data Collection'!$A$2:$A$54,0),MATCH(B166,'Data Collection'!$B$2:$E$2,0))} -> 0 | F166: {=IFERROR(_xludf.let(cell,INDEX('Data Collection'!$F$2:$I$54,MATCH(A166,'Data Collection'!$A$2:$A$54,0),MATCH(B166,'Data Collection'!$F$2:$I$2,0)),LEFT(cell, FIND("/", cell)-1) / MID(cell, FIND("/", cell)+1, LEN(cell))),"")} | J166: =IFERROR(AVERAGE(G166:I166),"")
A167: {=INDEX('Data Collection'!$A$3:$A$54, INT((ROW()-2)/4)+1)} -> 42 | B167: =INDEX({"VS-VS","VS-VV","VS-AV","VS-AS"}, MOD(ROW()-2,4)+1) -> VS-VV | C167: =IF(RIGHT(B167,2)="VS","Visual",IF(RIGHT(B167,2)="VV", "Visual",IF(RIGHT(B167,2)="AV","Auditory",IF(RIGHT(B167,2)="AS","Auditory")))) -> Visual | D167: =IF(RIGHT(B167,1)="S","Spatial",IF(RIGHT(B167,1)="V", "Verbal",IF(RIGHT(B167,1)="V","Verbal",IF(RIGHT(B167,1)="S","Spatial")))) -> Verbal | E167: {=INDEX('Data Collection'!$B$2:$E$54,MATCH(A167,'Data Collection'!$A$2:$A$54,0),MATCH(B167,'Data Collection'!$B$2:$E$2,0))} -> 0 | F167: {=IFERROR(_xludf.let(cell,INDEX('Data Collection'!$F$2:$I$54,MATCH(A167,'Data Collection'!$A$2:$A$54,0),MATCH(B167,'Data Collection'!$F$2:$I$2,0)),LEFT(cell, FIND("/", cell)-1) / MID(cell, FIND("/", cell)+1, LEN(cell))),"")} | J167: =IFERROR(AVERAGE(G167:I167),"")
A168: {=INDEX('Data Collection'!$A$3:$A$54, INT((ROW()-2)/4)+1)} -> 42 | B168: =INDEX({"VS-VS","VS-VV","VS-AV","VS-AS"}, MOD(ROW()-2,4)+1) -> VS-AV | C168: =IF(RIGHT(B168,2)="VS","Visual",IF(RIGHT(B168,2)="VV", "Visual",IF(RIGHT(B168,2)="AV","Auditory",IF(RIGHT(B168,2)="AS","Auditory")))) -> Auditory | D168: =IF(RIGHT(B168,1)="S","Spatial",IF(RIGHT(B168,1)="V", "Verbal",IF(RIGHT(B168,1)="V","Verbal",IF(RIGHT(B168,1)="S","Spatial")))) -> Verbal | E168: {=INDEX('Data Collection'!$B$2:$E$54,MATCH(A168,'Data Collection'!$A$2:$A$54,0),MATCH(B168,'Data Collection'!$B$2:$E$2,0))} -> 0 | F168: {=IFERROR(_xludf.let(cell,INDEX('Data Collection'!$F$2:$I$54,MATCH(A168,'Data Collection'!$A$2:$A$54,0),MATCH(B168,'Data Collection'!$F$2:$I$2,0)),LEFT(cell, FIND("/", cell)-1) / MID(cell, FIND("/", cell)+1, LEN(cell))),"")} | J168: =IFERROR(AVERAGE(G168:I168),"")
A169: {=INDEX('Data Collection'!$A$3:$A$54, INT((ROW()-2)/4)+1)} -> 42 | B169: =INDEX({"VS-VS","VS-VV","VS-AV","VS-AS"}, MOD(ROW()-2,4)+1) -> VS-AS | C169: =IF(RIGHT(B169,2)="VS","Visual",IF(RIGHT(B169,2)="VV", "Visual",IF(RIGHT(B169,2)="AV","Auditory",IF(RIGHT(B169,2)="AS","Auditory")))) -> Auditory | D169: =IF(RIGHT(B169,1)="S","Spatial",IF(RIGHT(B169,1)="V", "Verbal",IF(RIGHT(B169,1)="V","Verbal",IF(RIGHT(B169,1)="S","Spatial")))) -> Spatial | E169: {=INDEX('Data Collection'!$B$2:$E$54,MATCH(A169,'Data Collection'!$A$2:$A$54,0),MATCH(B169,'Data Collection'!$B$2:$E$2,0))} -> 0 | F169: {=IFERROR(_xludf.let(cell,INDEX('Data Collection'!$F$2:$I$54,MATCH(A169,'Data Collection'!$A$2:$A$54,0),MATCH(B169,'Data Collection'!$F$2:$I$2,0)),LEFT(cell, FIND("/", cell)-1) / MID(cell, FIND("/", cell)+1, LEN(cell))),"")} | J169: =IFERROR(AVERAGE(G169:I169),"")
A170: {=INDEX('Data Collection'!$A$3:$A$54, INT((ROW()-2)/4)+1)} -> 43 | B170: =INDEX({"VS-VS","VS-VV","VS-AV","VS-AS"}, MOD(ROW()-2,4)+1) -> VS-VS | C170: =IF(RIGHT(B170,2)="VS","Visual",IF(RIGHT(B170,2)="VV", "Visual",IF(RIGHT(B170,2)="AV","Auditory",IF(RIGHT(B170,2)="AS","Auditory")))) -> Visual | D170: =IF(RIGHT(B170,1)="S","Spatial",IF(RIGHT(B170,1)="V", "Verbal",IF(RIGHT(B170,1)="V","Verbal",IF(RIGHT(B170,1)="S","Spatial")))) -> Spatial | E170: {=INDEX('Data Collection'!$B$2:$E$54,MATCH(A170,'Data Collection'!$A$2:$A$54,0),MATCH(B170,'Data Collection'!$B$2:$E$2,0))} -> 0 | F170: {=IFERROR(_xludf.let(cell,INDEX('Data Collection'!$F$2:$I$54,MATCH(A170,'Data Collection'!$A$2:$A$54,0),MATCH(B170,'Data Collection'!$F$2:$I$2,0)),LEFT(cell, FIND("/", cell)-1) / MID(cell, FIND("/", cell)+1, LEN(cell))),"")} | J170: =IFERROR(AVERAGE(G170:I170),"")
A171: {=INDEX('Data Collection'!$A$3:$A$54, INT((ROW()-2)/4)+1)} -> 43 | B171: =INDEX({"VS-VS","VS-VV","VS-AV","VS-AS"}, MOD(ROW()-2,4)+1) -> VS-VV | C171: =IF(RIGHT(B171,2)="VS","Visual",IF(RIGHT(B171,2)="VV", "Visual",IF(RIGHT(B171,2)="AV","Auditory",IF(RIGHT(B171,2)="AS","Auditory")))) -> Visual | D171: =IF(RIGHT(B171,1)="S","Spatial",IF(RIGHT(B171,1)="V", "Verbal",IF(RIGHT(B171,1)="V","Verbal",IF(RIGHT(B171,1)="S","Spatial")))) -> Verbal | E171: {=INDEX('Data Collection'!$B$2:$E$54,MATCH(A171,'Data Collection'!$A$2:$A$54,0),MATCH(B171,'Data Collection'!$B$2:$E$2,0))} -> 0 | F171: {=IFERROR(_xludf.let(cell,INDEX('Data Collection'!$F$2:$I$54,MATCH(A171,'Data Collection'!$A$2:$A$54,0),MATCH(B171,'Data Collection'!$F$2:$I$2,0)),LEFT(cell, FIND("/", cell)-1) / MID(cell, FIND("/", cell)+1, LEN(cell))),"")} | J171: =IFERROR(AVERAGE(G171:I171),"")
A172: {=INDEX('Data Collection'!$A$3:$A$54, INT((ROW()-2)/4)+1)} -> 43 | B172: =INDEX({"VS-VS","VS-VV","VS-AV","VS-AS"}, MOD(ROW()-2,4)+1) -> VS-AV | C172: =IF(RIGHT(B172,2)="VS","Visual",IF(RIGHT(B172,2)="VV", "Visual",IF(RIGHT(B172,2)="AV","Auditory",IF(RIGHT(B172,2)="AS","Auditory")))) -> Auditory | D172: =IF(RIGHT(B172,1)="S","Spatial",IF(RIGHT(B172,1)="V", "Verbal",IF(RIGHT(B172,1)="V","Verbal",IF(RIGHT(B172,1)="S","Spatial")))) -> Verbal | E172: {=INDEX('Data Collection'!$B$2:$E$54,MATCH(A172,'Data Collection'!$A$2:$A$54,0),MATCH(B172,'Data Collection'!$B$2:$E$2,0))} -> 0 | F172: {=IFERROR(_xludf.let(cell,INDEX('Data Collection'!$F$2:$I$54,MATCH(A172,'Data Collection'!$A$2:$A$54,0),MATCH(B172,'Data Collection'!$F$2:$I$2,0)),LEFT(cell, FIND("/", cell)-1) / MID(cell, FIND("/", cell)+1, LEN(cell))),"")} | J172: =IFERROR(AVERAGE(G172:I172),"")
A173: {=INDEX('Data Collection'!$A$3:$A$54, INT((ROW()-2)/4)+1)} -> 43 | B173: =INDEX({"VS-VS","VS-VV","VS-AV","VS-AS"}, MOD(ROW()-2,4)+1) -> VS-AS | C173: =IF(RIGHT(B173,2)="VS","Visual",IF(RIGHT(B173,2)="VV", "Visual",IF(RIGHT(B173,2)="AV","Auditory",IF(RIGHT(B173,2)="AS","Auditory")))) -> Auditory | D173: =IF(RIGHT(B173,1)="S","Spatial",IF(RIGHT(B173,1)="V", "Verbal",IF(RIGHT(B173,1)="V","Verbal",IF(RIGHT(B173,1)="S","Spatial")))) -> Spatial | E173: {=INDEX('Data Collection'!$B$2:$E$54,MATCH(A173,'Data Collection'!$A$2:$A$54,0),MATCH(B173,'Data Collection'!$B$2:$E$2,0))} -> 0 | F173: {=IFERROR(_xludf.let(cell,INDEX('Data Collection'!$F$2:$I$54,MATCH(A173,'Data Collection'!$A$2:$A$54,0),MATCH(B173,'Data Collection'!$F$2:$I$2,0)),LEFT(cell, FIND("/", cell)-1) / MID(cell, FIND("/", cell)+1, LEN(cell))),"")} | J173: =IFERROR(AVERAGE(G173:I173),"")
... A201: {=INDEX('Data Collection'!$A$3:$A$54, INT((ROW()-2)/4)+1)} -> 50 | B201: =INDEX({"VS-VS","VS-VV","VS-AV","VS-AS"}, MOD(ROW()-2,4)+1) -> VS-AS | C201: =IF(RIGHT(B201,2)="VS","Visual",IF(RIGHT(B201,2)="VV", "Visual",IF(RIGHT(B201,2)="AV","Auditory",IF(RIGHT(B201,2)="AS","Auditory")))) -> Auditory | D201: =IF(RIGHT(B201,1)="S","Spatial",IF(RIGHT(B201,1)="V", "Verbal",IF(RIGHT(B201,1)="V","Verbal",IF(RIGHT(B201,1)="S","Spatial")))) -> Spatial | E201: {=INDEX('Data Collection'!$B$2:$E$54,MATCH(A201,'Data Collection'!$A$2:$A$54,0),MATCH(B201,'Data Collection'!$B$2:$E$2,0))} -> 0 | F201: {=IFERROR(_xludf.let(cell,INDEX('Data Collection'!$F$2:$I$54,MATCH(A201,'Data Collection'!$A$2:$A$54,0),MATCH(B201,'Data Collection'!$F$2:$I$2,0)),LEFT(cell, FIND("/", cell)-1) / MID(cell, FIND("/", cell)+1, LEN(cell))),"")} | J201: =IFERROR(AVERAGE(G201:I201),"")

Sheet Simulated Data
A1: Participant | B1: Base | C1: VS-VS | D1: VS-VV | E1: VS-AV | F1: VS-AS | H1: Simulated Data Descriptive Statistics Summary Table
A2: 1 | B2: =MAX(NORMINV(RAND(),'Collected Data'!I$4,'Collected Data'!I$5),0) -> 21.00925 | C2: =MAX(NORMINV(RAND(),'Collected Data'!J$4,'Collected Data'!J$5),0) -> 145.19434 | D2: =MAX(NORMINV(RAND(),'Collected Data'!K$4,'Collected Data'!K$5),0) -> 40.115024 | E2: =MAX(NORMINV(RAND(),'Collected Data'!L$4,'Collected Data'!L$5),0) -> 101.68153 | F2: =MAX(NORMINV(RAND(),'Collected Data'!M$4,'Collected Data'!M$5),0) -> 106.37444
A3: 2 | B3: =MAX(NORMINV(RAND(),'Collected Data'!I$4,'Collected Data'!I$5),0) -> 11.325914 | C3: =MAX(NORMINV(RAND(),'Collected Data'!J$4,'Collected Data'!J$5),0) -> 59.449663 | D3: =MAX(NORMINV(RAND(),'Collected Data'!K$4,'Collected Data'!K$5),0) -> 167.6011 | E3: =MAX(NORMINV(RAND(),'Collected Data'!L$4,'Collected Data'!L$5),0) -> 103.40036 | F3: =MAX(NORMINV(RAND(),'Collected Data'!M$4,'Collected Data'!M$5),0) -> 63.54268 | I3: Base | J3: VS-VS | K3: VS-VV | L3: VS-AV | M3: VS-AS
A4: 3 | B4: =MAX(NORMINV(RAND(),'Collected Data'!I$4,'Collected Data'!I$5),0) -> 27.443268 | C4: =MAX(NORMINV(RAND(),'Collected Data'!J$4,'Collected Data'!J$5),0) -> 82.696292 | D4: =MAX(NORMINV(RAND(),'Collected Data'!K$4,'Collected Data'!K$5),0) -> 194.19586 | E4: =MAX(NORMINV(RAND(),'Collected Data'!L$4,'Collected Data'!L$5),0) -> 83.301593 | F4: =MAX(NORMINV(RAND(),'Collected Data'!M$4,'Collected Data'!M$5),0) -> 84.742655 | H4: Mean | I4: =AVERAGE(B2:B101) -> 17.020699 | J4: =AVERAGE(C2:C101) -> 93.20675 | K4: =AVERAGE(D2:D101) -> 97.683044 | L4: =AVERAGE(E2:E101) -> 88.646019 | M4: =AVERAGE(F2:F101) -> 92.124828
A5: 4 | B5: =MAX(NORMINV(RAND(),'Collected Data'!I$4,'Collected Data'!I$5),0) -> 8.3598632 | C5: =MAX(NORMINV(RAND(),'Collected Data'!J$4,'Collected Data'!J$5),0) -> 64.460923 | D5: =MAX(NORMINV(RAND(),'Collected Data'!K$4,'Collected Data'!K$5),0) -> 126.74895 | E5: =MAX(NORMINV(RAND(),'Collected Data'!L$4,'Collected Data'!L$5),0) -> 92.958635 | F5: =MAX(NORMINV(RAND(),'Collected Data'!M$4,'Collected Data'!M$5),0) -> 97.168484 | H5: Std. Dev. | I5: =STDEV(B2:B101) -> 7.8787876 | J5: =STDEV(C2:C101) -> 33.101051 | K5: =STDEV(D2:D101) -> 57.13158 | L5: =STDEV(E2:E101) -> 49.315299 | M5: =STDEV(F2:F101) -> 41.091695
A6: 5 | B6: =MAX(NORMINV(RAND(),'Collected Data'!I$4,'Collected Data'!I$5),0) -> 20.342063 | C6: =MAX(NORMINV(RAND(),'Collected Data'!J$4,'Collected Data'!J$5),0) -> 105.35487 | D6: =MAX(NORMINV(RAND(),'Collected Data'!K$4,'Collected Data'!K$5),0) -> 75.637481 | E6: =MAX(NORMINV(RAND(),'Collected Data'!L$4,'Collected Data'!L$5),0) -> 126.32064 | F6: =MAX(NORMINV(RAND(),'Collected Data'!M$4,'Collected Data'!M$5),0) -> 61.214233 | H6: 25th Pct | I6: =PERCENTILE(B2:B101,0.25) -> 11.873031 | J6: =PERCENTILE(C2:C101,0.25) -> 72.987504 | K6: =PERCENTILE(D2:D101,0.25) -> 52.920098 | L6: =PERCENTILE(E2:E101,0.25) -> 59.510924 | M6: =PERCENTILE(F2:F101,0.25) -> 65.039719
A7: 6 | B7: =MAX(NORMINV(RAND(),'Collected Data'!I$4,'Collected Data'!I$5),0) -> 19.03108 | C7: =MAX(NORMINV(RAND(),'Collected Data'!J$4,'Collected Data'!J$5),0) -> 92.492069 | D7: =MAX(NORMINV(RAND(),'Collected Data'!K$4,'Collected Data'!K$5),0) -> 64.817633 | E7: =MAX(NORMINV(RAND(),'Collected Data'!L$4,'Collected Data'!L$5),0) -> 62.822134 | F7: =MAX(NORMINV(RAND(),'Collected Data'!M$4,'Collected Data'!M$5),0) -> 10.761637 | H7: Median | I7: =MEDIAN(B2:B101) -> 17.299351 | J7: =MEDIAN(C2:C101) -> 92.534264 | K7: =MEDIAN(D2:D101) -> 89.065259 | L7: =MEDIAN(E2:E101) -> 89.265547 | M7: =MEDIAN(F2:F101) -> 93.062694
A8: 7 | B8: =MAX(NORMINV(RAND(),'Collected Data'!I$4,'Collected Data'!I$5),0) -> 24.541553 | C8: =MAX(NORMINV(RAND(),'Collected Data'!J$4,'Collected Data'!J$5),0) -> 109.41006 | D8: =MAX(NORMINV(RAND(),'Collected Data'!K$4,'Collected Data'!K$5),0) -> 48.25834 | E8: =MAX(NORMINV(RAND(),'Collected Data'!L$4,'Collected Data'!L$5),0) -> 115.45707 | F8: =MAX(NORMINV(RAND(),'Collected Data'!M$4,'Collected Data'!M$5),0) -> 51.683258 | H8: 75th Pct | I8: =PERCENTILE(B2:B101,0.75) -> 20.846567 | J8: =PERCENTILE(C2:C101,0.75) -> 112.53919 | K8: =PERCENTILE(D2:D101,0.75) -> 140.83131 | L8: =PERCENTILE(E2:E101,0.75) -> 120.34839 | M8: =PERCENTILE(F2:F101,0.75) -> 120.76313
A9: 8 | B9: =MAX(NORMINV(RAND(),'Collected Data'!I$4,'Collected Data'!I$5),0) -> 14.55699 | C9: =MAX(NORMINV(RAND(),'Collected Data'!J$4,'Collected Data'!J$5),0) -> 100.23497 | D9: =MAX(NORMINV(RAND(),'Collected Data'!K$4,'Collected Data'!K$5),0) -> 160.59736 | E9: =MAX(NORMINV(RAND(),'Collected Data'!L$4,'Collected Data'!L$5),0) -> 128.08727 | F9: =MAX(NORMINV(RAND(),'Collected Data'!M$4,'Collected Data'!M$5),0) -> 89.455685 | H9: IQR | I9: =I8-I6 -> 8.9735355 | J9: =J8-J6 -> 39.551684 | K9: =K8-K6 -> 87.911209 | L9: =L8-L6 -> 60.837466 | M9: =M8-M6 -> 55.723406
A10: 9 | B10: =MAX(NORMINV(RAND(),'Collected Data'!I$4,'Collected Data'!I$5),0) -> 18.026916 | C10: =MAX(NORMINV(RAND(),'Collected Data'!J$4,'Collected Data'!J$5),0) -> 107.93659 | D10: =MAX(NORMINV(RAND(),'Collected Data'!K$4,'Collected Data'!K$5),0) -> 39.108678 | E10: =MAX(NORMINV(RAND(),'Collected Data'!L$4,'Collected Data'!L$5),0) -> 76.142778 | F10: =MAX(NORMINV(RAND(),'Collected Data'!M$4,'Collected Data'!M$5),0) -> 28.44835 | H10: Minimum | I10: =MIN(B2:B101) -> 0 | J10: =MIN(C2:C101) -> 0 | K10: =MIN(D2:D101) -> 0 | L10: =MIN(E2:E101) -> 0 | M10: =MIN(F2:F101) -> 0.18933406
A11: 10 | B11: =MAX(NORMINV(RAND(),'Collected Data'!I$4,'Collected Data'!I$5),0) -> 13.449412 | C11: =MAX(NORMINV(RAND(),'Collected Data'!J$4,'Collected Data'!J$5),0) -> 27.549807 | D11: =MAX(NORMINV(RAND(),'Collected Data'!K$4,'Collected Data'!K$5),0) -> 54.649524 | E11: =MAX(NORMINV(RAND(),'Collected Data'!L$4,'Collected Data'!L$5),0) -> 126.12027 | F11: =MAX(NORMINV(RAND(),'Collected Data'!M$4,'Collected Data'!M$5),0) -> 83.892227 | H11: Maximum | I11: =MAX(B2:B101) -> 36.112389 | J11: =MAX(C2:C101) -> 170.90536 | K11: =MAX(D2:D101) -> 226.72456 | L11: =MAX(E2:E101) -> 241.43375 | M11: =MAX(F2:F101) -> 186.71381
A12: 11 | B12: =MAX(NORMINV(RAND(),'Collected Data'!I$4,'Collected Data'!I$5),0) -> 20.537064 | C12: =MAX(NORMINV(RAND(),'Collected Data'!J$4,'Collected Data'!J$5),0) -> 126.79065 | D12: =MAX(NORMINV(RAND(),'Collected Data'!K$4,'Collected Data'!K$5),0) -> 91.960472 | E12: =MAX(NORMINV(RAND(),'Collected Data'!L$4,'Collected Data'!L$5),0) -> 33.743572 | F12: =MAX(NORMINV(RAND(),'Collected Data'!M$4,'Collected Data'!M$5),0) -> 184.72988 | H12: Variance | I12: =VAR(B2:B101) -> 62.075295 | J12: =VAR(C2:C101) -> 1095.6795 | K12: =VAR(D2:D101) -> 3264.0175 | L12: =VAR(E2:E101) -> 2431.9987 | M12: =VAR(F2:F101) -> 1688.5274
A13: 12 | B13: =MAX(NORMINV(RAND(),'Collected Data'!I$4,'Collected Data'!I$5),0) -> 20.46472 | C13: =MAX(NORMINV(RAND(),'Collected Data'!J$4,'Collected Data'!J$5),0) -> 0 | D13: =MAX(NORMINV(RAND(),'Collected Data'!K$4,'Collected Data'!K$5),0) -> 20.124719 | E13: =MAX(NORMINV(RAND(),'Collected Data'!L$4,'Collected Data'!L$5),0) -> 159.75006 | F13: =MAX(NORMINV(RAND(),'Collected Data'!M$4,'Collected Data'!M$5),0) -> 9.2944714
A14: 13 | B14: =MAX(NORMINV(RAND(),'Collected Data'!I$4,'Collected Data'!I$5),0) -> 20.164726 | C14: =MAX(NORMINV(RAND(),'Collected Data'!J$4,'Collected Data'!J$5),0) -> 145.21864 | D14: =MAX(NORMINV(RAND(),'Collected Data'!K$4,'Collected Data'!K$5),0) -> 54.577605 | E14: =MAX(NORMINV(RAND(),'Collected Data'!L$4,'Collected Data'!L$5),0) -> 241.43375 | F14: =MAX(NORMINV(RAND(),'Collected Data'!M$4,'Collected Data'!M$5),0) -> 130.27196 | J14: VS-VS | K14: VS-VV | L14: VS-AV | M14: VS-AS
A15: 14 | B15: =MAX(NORMINV(RAND(),'Collected Data'!I$4,'Collected Data'!I$5),0) -> 16.491012 | C15: =MAX(NORMINV(RAND(),'Collected Data'!J$4,'Collected Data'!J$5),0) -> 115.20421 | D15: =MAX(NORMINV(RAND(),'Collected Data'!K$4,'Collected Data'!K$5),0) -> 196.88143 | E15: =MAX(NORMINV(RAND(),'Collected Data'!L$4,'Collected Data'!L$5),0) -> 59.925768 | F15: =MAX(NORMINV(RAND(),'Collected Data'!M$4,'Collected Data'!M$5),0) -> 0.18933406 | H15: Base Score | J15: =AVERAGE($B$2:$B$101) -> 17.020699 | K15: =AVERAGE($B$2:$B$101) -> 17.020699 | L15: =AVERAGE($B$2:$B$101) -> 17.020699 | M15: =AVERAGE($B$2:$B$101) -> 17.020699
A16: 15 | B16: =MAX(NORMINV(RAND(),'Collected Data'!I$4,'Collected Data'!I$5),0) -> 16.453103 | C16: =MAX(NORMINV(RAND(),'Collected Data'!J$4,'Collected Data'!J$5),0) -> 147.70164 | D16: =MAX(NORMINV(RAND(),'Collected Data'!K$4,'Collected Data'!K$5),0) -> 74.241519 | E16: =MAX(NORMINV(RAND(),'Collected Data'!L$4,'Collected Data'!L$5),0) -> 3.9241456 | F16: =MAX(NORMINV(RAND(),'Collected Data'!M$4,'Collected Data'!M$5),0) -> 106.8904 | H16: Degradation | J16: =J17-J15 -> 76.186051 | K16: =K17-K15 -> 80.662345 | L16: =L17-L15 -> 71.62532 | M16: =M17-M15 -> 75.104129
A17: 16 | B17: =MAX(NORMINV(RAND(),'Collected Data'!I$4,'Collected Data'!I$5),0) -> 32.912655 | C17: =MAX(NORMINV(RAND(),'Collected Data'!J$4,'Collected Data'!J$5),0) -> 75.147546 | D17: =MAX(NORMINV(RAND(),'Collected Data'!K$4,'Collected Data'!K$5),0) -> 150.85222 | E17: =MAX(NORMINV(RAND(),'Collected Data'!L$4,'Collected Data'!L$5),0) -> 67.842558 | F17: =MAX(NORMINV(RAND(),'Collected Data'!M$4,'Collected Data'!M$5),0) -> 17.495444 | H17: Mean | J17: =AVERAGE(C2:C101) -> 93.20675 | K17: =AVERAGE(D2:D101) -> 97.683044 | L17: =AVERAGE(E2:E101) -> 88.646019 | M17: =AVERAGE(F2:F101) -> 92.124828
A18: 17 | B18: =MAX(NORMINV(RAND(),'Collected Data'!I$4,'Collected Data'!I$5),0) -> 10.963615 | C18: =MAX(NORMINV(RAND(),'Collected Data'!J$4,'Collected Data'!J$5),0) -> 132.52354 | D18: =MAX(NORMINV(RAND(),'Collected Data'!K$4,'Collected Data'!K$5),0) -> 58.284686 | E18: =MAX(NORMINV(RAND(),'Collected Data'!L$4,'Collected Data'!L$5),0) -> 95.658599 | F18: =MAX(NORMINV(RAND(),'Collected Data'!M$4,'Collected Data'!M$5),0) -> 112.26729
A19: 18 | B19: =MAX(NORMINV(RAND(),'Collected Data'!I$4,'Collected Data'!I$5),0) -> 14.417451 | C19: =MAX(NORMINV(RAND(),'Collected Data'!J$4,'Collected Data'!J$5),0) -> 170.90536 | D19: =MAX(NORMINV(RAND(),'Collected Data'!K$4,'Collected Data'!K$5),0) -> 50.135487 | E19: =MAX(NORMINV(RAND(),'Collected Data'!L$4,'Collected Data'!L$5),0) -> 9.8872693 | F19: =MAX(NORMINV(RAND(),'Collected Data'!M$4,'Collected Data'!M$5),0) -> 63.451722
A20: 19 | B20: =MAX(NORMINV(RAND(),'Collected Data'!I$4,'Collected Data'!I$5),0) -> 12.037028 | C20: =MAX(NORMINV(RAND(),'Collected Data'!J$4,'Collected Data'!J$5),0) -> 98.591661 | D20: =MAX(NORMINV(RAND(),'Collected Data'!K$4,'Collected Data'!K$5),0) -> 32.096697 | E20: =MAX(NORMINV(RAND(),'Collected Data'!L$4,'Collected Data'!L$5),0) -> 90.199304 | F20: =MAX(NORMINV(RAND(),'Collected Data'!M$4,'Collected Data'!M$5),0) -> 130.00841
A21: 20 | B21: =MAX(NORMINV(RAND(),'Collected Data'!I$4,'Collected Data'!I$5),0) -> 18.560202 | C21: =MAX(NORMINV(RAND(),'Collected Data'!J$4,'Collected Data'!J$5),0) -> 34.137129 | D21: =MAX(NORMINV(RAND(),'Collected Data'!K$4,'Collected Data'!K$5),0) -> 120.17608 | E21: =MAX(NORMINV(RAND(),'Collected Data'!L$4,'Collected Data'!L$5),0) -> 49.651686 | F21: =MAX(NORMINV(RAND(),'Collected Data'!M$4,'Collected Data'!M$5),0) -> 71.559679
A22: 21 | B22: =MAX(NORMINV(RAND(),'Collected Data'!I$4,'Collected Data'!I$5),0) -> 21.377771 | C22: =MAX(NORMINV(RAND(),'Collected Data'!J$4,'Collected Data'!J$5),0) -> 83.433695 | D22: =MAX(NORMINV(RAND(),'Collected Data'!K$4,'Collected Data'!K$5),0) -> 79.192083 | E22: =MAX(NORMINV(RAND(),'Collected Data'!L$4,'Collected Data'!L$5),0) -> 34.371286 | F22: =MAX(NORMINV(RAND(),'Collected Data'!M$4,'Collected Data'!M$5),0) -> 86.750869
A23: 22 | B23: =MAX(NORMINV(RAND(),'Collected Data'!I$4,'Collected Data'!I$5),0) -> 8.0617343 | C23: =MAX(NORMINV(RAND(),'Collected Data'!J$4,'Collected Data'!J$5),0) -> 87.777428 | D23: =MAX(NORMINV(RAND(),'Collected Data'!K$4,'Collected Data'!K$5),0) -> 0 | E23: =MAX(NORMINV(RAND(),'Collected Data'!L$4,'Collected Data'!L$5),0) -> 0.68462024 | F23: =MAX(NORMINV(RAND(),'Collected Data'!M$4,'Collected Data'!M$5),0) -> 105.69499
